Workbook

Sheet Raw_Data
A1: RAW DATA — 120 Transaction Records | Contains Intentional Errors
A2: Transaction ID | B2: Date | C2: Customer Name | D2: Product | E2: Quantity | F2: Unit Price ($) | G2: Total Amount ($) | H2: Payment Status
A3: TXN1081 | B3: 45376 | C3: Eta Partners | D3: Tablet | E3: 10 | F3: 32000 | G3: 320000 | H3: Refunded
A4: TXN1082 | B4: 45402 | C4: Nu Ventures | D4: Printer | E4: 17 | F4: 18000 | G4: 306000 | H4: Paid
A5: TXN1083 | B5: 45550 | C5: Iota Ltd | D5: Mouse | E5: 1 | F5: 1200 | G5: 1320 | H5: Pending
A6: TXN1020 | B6: 45511 | C6: Beta Ltd | D6: Keyboard | E6: 8 | F6: 3500 | G6: 28000 | H6: Paid
A7: TXN1085 | B7: 45647 | C7: Acme Corp | D7: Tablet | E7: 14 | F7: 32000 | G7: 448000 | H7: Refunded
A8: TXN1086 | B8: 45309 | C8: Zeta Group | D8: Scanner | E8: 16 | F8: 12000 | G8: 192000 | H8: Paid
A9: TXN1087 | B9: 45624 | C9: [BLANK] | D9: Webcam | E9: 1 | F9: 4500 | G9: 4500 | H9: Paid
A10: TXN1088 | B10: 45337 | C10: Beta Ltd | D10: Laptop | E10: 15 | F10: 85000 | G10: 1275000 | H10: Paid
A11: TXN1020 | B11: 45467 | C11: Eta Partners | D11: Printer | E11: 5 | F11: 18000 | G11: 90000 | H11: Paid
A12: TXN1090 | B12: 45632 | C12: Acme Corp | D12: Printer | E12: 8 | F12: 18000 | G12: 144000 | H12: Paid
A13: TXN1091 | B13: 45393 | C13: Delta Co | D13: USB Hub | E13: 3 | F13: 2200 | G13: 7260 | H13: Refunded
A14: TXN1092 | B14: 45578 | C14: Xi Corp | D14: [BLANK] | E14: 13 | F14: 5000 | G14: 65000 | H14: Paid
... A23: TXN1101 | B23: 45511 | C23: Zeta Group | D23: Keyboard | E23: 2 | F23: 3500 | G23: 7000 | H23: Paid
A24: TXN1102 | C24: Eta Partners | D24: Keyboard | E24: 19 | F24: 3500 | G24: 66500 | H24: Paid
A25: TXN1103 | B25: 45469 | C25: Theta Corp | D25: Scanner | E25: 13 | F25: 12000 | G25: 156000 | H25: Paid
A26: TXN1005 | B26: 45375 | C26: Iota Ltd | D26: Monitor | E26: 15 | F26: 22000 | G26: 330000 | H26: Failed
A27: TXN1105 | B27: 45539 | C27: Acme Corp | D27: Headphones | E27: 2 | F27: 8500 | G27: 17000 | H27: Pending
A28: TXN1106 | B28: 45629 | C28: Epsilon LLC | D28: Laptop | E28: 14 | F28: 85000 | G28: 1190000 | H28: Paid
A29: TXN1107 | B29: 45379 | C29: [BLANK] | D29: Tablet | E29: 3 | F29: 32000 | G29: 144000 | H29: Paid
A30: TXN1108 | B30: 45369 | C30: Mu Holdings | D30: Printer | E30: 2 | F30: 18000 | G30: 36000 | H30: Pending
A31: TXN1005 | B31: 45624 | C31: Iota Ltd | D31: Printer | E31: 1 | F31: 18000 | G31: 18000 | H31: Paid
A32: TXN1110 | B32: 45479 | C32: Nu Ventures | D32: Keyboard | E32: 12 | F32: 3500 | G32: 42000 | H32: Failed
A33: TXN1111 | B33: 45540 | C33: Kappa Inc | D33: Printer | E33: 10 | F33: 18000 | G33: 180000 | H33: Paid
A34: TXN1112 | B34: 45565 | C34: Kappa Inc | D34: [BLANK] | E34: 9 | F34: 5000 | G34: 45000 | H34: Paid
A35: TXN1113 | B35: 45297 | C35: Eta Partners | D35: Keyboard | E35: 1 | F35: 3500 | G35: 3500 | H35: Pending
A36: TXN1020 | B36: 45458 | C36: Lambda Co | D36: Mouse | E36: 19 | F36: 1200 | G36: 22800 | H36: Failed
... A43: TXN1121 | B43: 45601 | C43: Mu Holdings | D43: Scanner | E43: 2 | F43: 12000 | G43: 24000 | H43: Paid
A44: TXN1122 | C44: Eta Partners | D44: Printer | E44: 3 | F44: 18000 | G44: 54000 | H44: Failed
A45: TXN1123 | B45: 45582 | C45: Gamma Inc | D45: Mouse | E45: 9 | F45: 1200 | G45: 13500 | H45: Pending
A46: TXN1001 | B46: 45417 | C46: Eta Partners | D46: Keyboard | E46: 10 | F46: 3500 | G46: 35000 | H46: Pending
A47: TXN1125 | B47: 45549 | C47: Nu Ventures | D47: Scanner | E47: -16 | F47: 12000 | G47: -192000 | H47: Paid
A48: TXN1126 | B48: 45571 | C48: Kappa Inc | D48: Laptop | E48: 17 | F48: 85000 | G48: 1445000 | H48: Pending
A49: TXN1127 | B49: 45556 | C49: [BLANK] | D49: Headphones | E49: 10 | F49: 8500 | G49: 85000 | H49: Paid
A50: TXN1128 | B50: 45324 | C50: Kappa Inc | D50: Webcam | E50: 7 | F50: 4500 | G50: 31500 | H50: Pending
A51: TXN1001 | B51: 45454 | C51: Lambda Co | D51: Tablet | E51: 4 | F51: 32000 | G51: 128000 | H51: Paid
A52: TXN1130 | B52: 45625 | C52: Beta Ltd | D52: Printer | E52: 17 | F52: 18000 | G52: 306000 | H52: Paid
A53: TXN1131 | B53: 45640 | C53: Lambda Co | D53: Printer | E53: 16 | F53: 18000 | G53: 172800 | H53: Failed
A54: TXN1132 | B54: 45497 | C54: Beta Ltd | D54: [BLANK] | E54: 8 | F54: 5000 | G54: 40000 | H54: Paid
...

Sheet Cleaned_Data
A1: CLEANED DATA — Formulas Applied: TRIM | IF | XLOOKUP | Corrected Totals
A2: Transaction ID | B2: Date | C2: Customer Name (TRIM) | D2: Product | E2: Quantity | F2: Unit Price ($) | G2: Corrected Total ($) | H2: Payment Status | I2: Row Flag
A3: =IF(Raw_Data!A3="","Missing",Raw_Data!A3) | B3: =IF(Raw_Data!B3="",DATE(2024,1,1),Raw_Data!B3) | C3: =TRIM(IF(Raw_Data!C3="","Unknown Customer",Raw_Data!C3)) | D3: =IF(Raw_Data!D3="","Unknown Product",Raw_Data!D3) | E3: =ABS(Raw_Data!E3) | F3: =Raw_Data!F3 | G3: =E3*F3 | H3: =IFERROR(XLOOKUP(Raw_Data!A3,Raw_Data!A:A,Raw_Data!H:H),"N/A") | I3: Clean
A4: =IF(Raw_Data!A4="","Missing",Raw_Data!A4) | B4: =IF(Raw_Data!B4="",DATE(2024,1,1),Raw_Data!B4) | C4: =TRIM(IF(Raw_Data!C4="","Unknown Customer",Raw_Data!C4)) | D4: =IF(Raw_Data!D4="","Unknown Product",Raw_Data!D4) | E4: =ABS(Raw_Data!E4) | F4: =Raw_Data!F4 | G4: =E4*F4 | H4: =IFERROR(XLOOKUP(Raw_Data!A4,Raw_Data!A:A,Raw_Data!H:H),"N/A") | I4: Clean
A5: =IF(Raw_Data!A5="","Missing",Raw_Data!A5) | B5: =IF(Raw_Data!B5="",DATE(2024,1,1),Raw_Data!B5) | C5: =TRIM(IF(Raw_Data!C5="","Unknown Customer",Raw_Data!C5)) | D5: =IF(Raw_Data!D5="","Unknown Product",Raw_Data!D5) | E5: =ABS(Raw_Data!E5) | F5: =Raw_Data!F5 | G5: =E5*F5 | H5: =IFERROR(XLOOKUP(Raw_Data!A5,Raw_Data!A:A,Raw_Data!H:H),"N/A") | I5: Fixed
A6: =IF(Raw_Data!A6="","Missing",Raw_Data!A6) | B6: =IF(Raw_Data!B6="",DATE(2024,1,1),Raw_Data!B6) | C6: =TRIM(IF(Raw_Data!C6="","Unknown Customer",Raw_Data!C6)) | D6: =IF(Raw_Data!D6="","Unknown Product",Raw_Data!D6) | E6: =ABS(Raw_Data!E6) | F6: =Raw_Data!F6 | G6: =E6*F6 | H6: =IFERROR(XLOOKUP(Raw_Data!A6,Raw_Data!A:A,Raw_Data!H:H),"N/A") | I6: Fixed
A7: =IF(Raw_Data!A7="","Missing",Raw_Data!A7) | B7: =IF(Raw_Data!B7="",DATE(2024,1,1),Raw_Data!B7) | C7: =TRIM(IF(Raw_Data!C7="","Unknown Customer",Raw_Data!C7)) | D7: =IF(Raw_Data!D7="","Unknown Product",Raw_Data!D7) | E7: =ABS(Raw_Data!E7) | F7: =Raw_Data!F7 | G7: =E7*F7 | H7: =IFERROR(XLOOKUP(Raw_Data!A7,Raw_Data!A:A,Raw_Data!H:H),"N/A") | I7: Clean
A8: =IF(Raw_Data!A8="","Missing",Raw_Data!A8) | B8: =IF(Raw_Data!B8="",DATE(2024,1,1),Raw_Data!B8) | C8: =TRIM(IF(Raw_Data!C8="","Unknown Customer",Raw_Data!C8)) | D8: =IF(Raw_Data!D8="","Unknown Product",Raw_Data!D8) | E8: =ABS(Raw_Data!E8) | F8: =Raw_Data!F8 | G8: =E8*F8 | H8: =IFERROR(XLOOKUP(Raw_Data!A8,Raw_Data!A:A,Raw_Data!H:H),"N/A") | I8: Clean
A9: =IF(Raw_Data!A9="","Missing",Raw_Data!A9) | B9: =IF(Raw_Data!B9="",DATE(2024,1,1),Raw_Data!B9) | C9: =TRIM(IF(Raw_Data!C9="","Unknown Customer",Raw_Data!C9)) | D9: =IF(Raw_Data!D9="","Unknown Product",Raw_Data!D9) | E9: =ABS(Raw_Data!E9) | F9: =Raw_Data!F9 | G9: =E9*F9 | H9: =IFERROR(XLOOKUP(Raw_Data!A9,Raw_Data!A:A,Raw_Data!H:H),"N/A") | I9: Fixed
A10: =IF(Raw_Data!A10="","Missing",Raw_Data!A10) | B10: =IF(Raw_Data!B10="",DATE(2024,1,1),Raw_Data!B10) | C10: =TRIM(IF(Raw_Data!C10="","Unknown Customer",Raw_Data!C10)) | D10: =IF(Raw_Data!D10="","Unknown Product",Raw_Data!D10) | E10: =ABS(Raw_Data!E10) | F10: =Raw_Data!F10 | G10: =E10*F10 | H10: =IFERROR(XLOOKUP(Raw_Data!A10,Raw_Data!A:A,Raw_Data!H:H),"N/A") | I10: Clean
A11: =IF(Raw_Data!A12="","Missing",Raw_Data!A12) | B11: =IF(Raw_Data!B12="",DATE(2024,1,1),Raw_Data!B12) | C11: =TRIM(IF(Raw_Data!C12="","Unknown Customer",Raw_Data!C12)) | D11: =IF(Raw_Data!D12="","Unknown Product",Raw_Data!D12) | E11: =ABS(Raw_Data!E12) | F11: =Raw_Data!F12 | G11: =E11*F11 | H11: =IFERROR(XLOOKUP(Raw_Data!A12,Raw_Data!A:A,Raw_Data!H:H),"N/A") | I11: Clean
A12: =IF(Raw_Data!A13="","Missing",Raw_Data!A13) | B12: =IF(Raw_Data!B13="",DATE(2024,1,1),Raw_Data!B13) | C12: =TRIM(IF(Raw_Data!C13="","Unknown Customer",Raw_Data!C13)) | D12: =IF(Raw_Data!D13="","Unknown Product",Raw_Data!D13) | E12: =ABS(Raw_Data!E13) | F12: =Raw_Data!F13 | G12: =E12*F12 | H12: =IFERROR(XLOOKUP(Raw_Data!A13,Raw_Data!A:A,Raw_Data!H:H),"N/A") | I12: Fixed
A13: =IF(Raw_Data!A14="","Missing",Raw_Data!A14) | B13: =IF(Raw_Data!B14="",DATE(2024,1,1),Raw_Data!B14) | C13: =TRIM(IF(Raw_Data!C14="","Unknown Customer",Raw_Data!C14)) | D13: =IF(Raw_Data!D14="","Unknown Product",Raw_Data!D14) | E13: =ABS(Raw_Data!E14) | F13: =Raw_Data!F14 | G13: =E13*F13 | H13: =IFERROR(XLOOKUP(Raw_Data!A14,Raw_Data!A:A,Raw_Data!H:H),"N/A") | I13: Fixed
A14: =IF(Raw_Data!A15="","Missing",Raw_Data!A15) | B14: =IF(Raw_Data!B15="",DATE(2024,1,1),Raw_Data!B15) | C14: =TRIM(IF(Raw_Data!C15="","Unknown Customer",Raw_Data!C15)) | D14: =IF(Raw_Data!D15="","Unknown Product",Raw_Data!D15) | E14: =ABS(Raw_Data!E15) | F14: =Raw_Data!F15 | G14: =E14*F14 | H14: =IFERROR(XLOOKUP(Raw_Data!A15,Raw_Data!A:A,Raw_Data!H:H),"N/A") | I14: Clean
A15: =IF(Raw_Data!A16="","Missing",Raw_Data!A16) | B15: =IF(Raw_Data!B16="",DATE(2024,1,1),Raw_Data!B16) | C15: =TRIM(IF(Raw_Data!C16="","Unknown Customer",Raw_Data!C16)) | D15: =IF(Raw_Data!D16="","Unknown Product",Raw_Data!D16) | E15: =ABS(Raw_Data!E16) | F15: =Raw_Data!F16 | G15: =E15*F15 | H15: =IFERROR(XLOOKUP(Raw_Data!A16,Raw_Data!A:A,Raw_Data!H:H),"N/A") | I15: Fixed
A16: =IF(Raw_Data!A17="","Missing",Raw_Data!A17) | B16: =IF(Raw_Data!B17="",DATE(2024,1,1),Raw_Data!B17) | C16: =TRIM(IF(Raw_Data!C17="","Unknown Customer",Raw_Data!C17)) | D16: =IF(Raw_Data!D17="","Unknown Product",Raw_Data!D17) | E16: =ABS(Raw_Data!E17) | F16: =Raw_Data!F17 | G16: =E16*F16 | H16: =IFERROR(XLOOKUP(Raw_Data!A17,Raw_Data!A:A,Raw_Data!H:H),"N/A") | I16: Clean
A17: =IF(Raw_Data!A18="","Missing",Raw_Data!A18) | B17: =IF(Raw_Data!B18="",DATE(2024,1,1),Raw_Data!B18) | C17: =TRIM(IF(Raw_Data!C18="","Unknown Customer",Raw_Data!C18)) | D17: =IF(Raw_Data!D18="","Unknown Product",Raw_Data!D18) | E17: =ABS(Raw_Data!E18) | F17: =Raw_Data!F18 | G17: =E17*F17 | H17: =IFERROR(XLOOKUP(Raw_Data!A18,Raw_Data!A:A,Raw_Data!H:H),"N/A") | I17: Clean
A18: =IF(Raw_Data!A19="","Missing",Raw_Data!A19) | B18: =IF(Raw_Data!B19="",DATE(2024,1,1),Raw_Data!B19) | C18: =TRIM(IF(Raw_Data!C19="","Unknown Customer",Raw_Data!C19)) | D18: =IF(Raw_Data!D19="","Unknown Product",Raw_Data!D19) | E18: =ABS(Raw_Data!E19) | F18: =Raw_Data!F19 | G18: =E18*F18 | H18: =IFERROR(XLOOKUP(Raw_Data!A19,Raw_Data!A:A,Raw_Data!H:H),"N/A") | I18: Fixed
A19: =IF(Raw_Data!A20="","Missing",Raw_Data!A20) | B19: =IF(Raw_Data!B20="",DATE(2024,1,1),Raw_Data!B20) | C19: =TRIM(IF(Raw_Data!C20="","Unknown Customer",Raw_Data!C20)) | D19: =IF(Raw_Data!D20="","Unknown Product",Raw_Data!D20) | E19: =ABS(Raw_Data!E20) | F19: =Raw_Data!F20 | G19: =E19*F19 | H19: =IFERROR(XLOOKUP(Raw_Data!A20,Raw_Data!A:A,Raw_Data!H:H),"N/A") | I19: Clean
A20: =IF(Raw_Data!A21="","Missing",Raw_Data!A21) | B20: =IF(Raw_Data!B21="",DATE(2024,1,1),Raw_Data!B21) | C20: =TRIM(IF(Raw_Data!C21="","Unknown Customer",Raw_Data!C21)) | D20: =IF(Raw_Data!D21="","Unknown Product",Raw_Data!D21) | E20: =ABS(Raw_Data!E21) | F20: =Raw_Data!F21 | G20: =E20*F20 | H20: =IFERROR(XLOOKUP(Raw_Data!A21,Raw_Data!A:A,Raw_Data!H:H),"N/A") | I20: Fixed
A21: =IF(Raw_Data!A22="","Missing",Raw_Data!A22) | B21: =IF(Raw_Data!B22="",DATE(2024,1,1),Raw_Data!B22) | C21: =TRIM(IF(Raw_Data!C22="","Unknown Customer",Raw_Data!C22)) | D21: =IF(Raw_Data!D22="","Unknown Product",Raw_Data!D22) | E21: =ABS(Raw_Data!E22) | F21: =Raw_Data!F22 | G21: =E21*F21 | H21: =IFERROR(XLOOKUP(Raw_Data!A22,Raw_Data!A:A,Raw_Data!H:H),"N/A") | I21: Clean
A22: =IF(Raw_Data!A23="","Missing",Raw_Data!A23) | B22: =IF(Raw_Data!B23="",DATE(2024,1,1),Raw_Data!B23) | C22: =TRIM(IF(Raw_Data!C23="","Unknown Customer",Raw_Data!C23)) | D22: =IF(Raw_Data!D23="","Unknown Product",Raw_Data!D23) | E22: =ABS(Raw_Data!E23) | F22: =Raw_Data!F23 | G22: =E22*F22 | H22: =IFERROR(XLOOKUP(Raw_Data!A23,Raw_Data!A:A,Raw_Data!H:H),"N/A") | I22: Clean
... A24: =IF(Raw_Data!A25="","Missing",Raw_Data!A25) | B24: =IF(Raw_Data!B25="",DATE(2024,1,1),Raw_Data!B25) | C24: =TRIM(IF(Raw_Data!C25="","Unknown Customer",Raw_Data!C25)) | D24: =IF(Raw_Data!D25="","Unknown Product",Raw_Data!D25) | E24: =ABS(Raw_Data!E25) | F24: =Raw_Data!F25 | G24: =E24*F24 | H24: =IFERROR(XLOOKUP(Raw_Data!A25,Raw_Data!A:A,Raw_Data!H:H),"N/A") | I24: Clean
A25: =IF(Raw_Data!A27="","Missing",Raw_Data!A27) | B25: =IF(Raw_Data!B27="",DATE(2024,1,1),Raw_Data!B27) | C25: =TRIM(IF(Raw_Data!C27="","Unknown Customer",Raw_Data!C27)) | D25: =IF(Raw_Data!D27="","Unknown Product",Raw_Data!D27) | E25: =ABS(Raw_Data!E27) | F25: =Raw_Data!F27 | G25: =E25*F25 | H25: =IFERROR(XLOOKUP(Raw_Data!A27,Raw_Data!A:A,Raw_Data!H:H),"N/A") | I25: Clean
A26: =IF(Raw_Data!A28="","Missing",Raw_Data!A28) | B26: =IF(Raw_Data!B28="",DATE(2024,1,1),Raw_Data!B28) | C26: =TRIM(IF(Raw_Data!C28="","Unknown Customer",Raw_Data!C28)) | D26: =IF(Raw_Data!D28="","Unknown Product",Raw_Data!D28) | E26: =ABS(Raw_Data!E28) | F26: =Raw_Data!F28 | G26: =E26*F26 | H26: =IFERROR(XLOOKUP(Raw_Data!A28,Raw_Data!A:A,Raw_Data!H:H),"N/A") | I26: Clean
A27: =IF(Raw_Data!A29="","Missing",Raw_Data!A29) | B27: =IF(Raw_Data!B29="",DATE(2024,1,1),Raw_Data!B29) | C27: =TRIM(IF(Raw_Data!C29="","Unknown Customer",Raw_Data!C29)) | D27: =IF(Raw_Data!D29="","Unknown Product",Raw_Data!D29) | E27: =ABS(Raw_Data!E29) | F27: =Raw_Data!F29 | G27: =E27*F27 | H27: =IFERROR(XLOOKUP(Raw_Data!A29,Raw_Data!A:A,Raw_Data!H:H),"N/A") | I27: Fixed
A28: =IF(Raw_Data!A30="","Missing",Raw_Data!A30) | B28: =IF(Raw_Data!B30="",DATE(2024,1,1),Raw_Data!B30) | C28: =TRIM(IF(Raw_Data!C30="","Unknown Customer",Raw_Data!C30)) | D28: =IF(Raw_Data!D30="","Unknown Product",Raw_Data!D30) | E28: =ABS(Raw_Data!E30) | F28: =Raw_Data!F30 | G28: =E28*F28 | H28: =IFERROR(XLOOKUP(Raw_Data!A30,Raw_Data!A:A,Raw_Data!H:H),"N/A") | I28: Clean
A29: =IF(Raw_Data!A32="","Missing",Raw_Data!A32) | B29: =IF(Raw_Data!B32="",DATE(2024,1,1),Raw_Data!B32) | C29: =TRIM(IF(Raw_Data!C32="","Unknown Customer",Raw_Data!C32)) | D29: =IF(Raw_Data!D32="","Unknown Product",Raw_Data!D32) | E29: =ABS(Raw_Data!E32) | F29: =Raw_Data!F32 | G29: =E29*F29 | H29: =IFERROR(XLOOKUP(Raw_Data!A32,Raw_Data!A:A,Raw_Data!H:H),"N/A") | I29: Clean
A30: =IF(Raw_Data!A33="","Missing",Raw_Data!A33) | B30: =IF(Raw_Data!B33="",DATE(2024,1,1),Raw_Data!B33) | C30: =TRIM(IF(Raw_Data!C33="","Unknown Customer",Raw_Data!C33)) | D30: =IF(Raw_Data!D33="","Unknown Product",Raw_Data!D33) | E30: =ABS(Raw_Data!E33) | F30: =Raw_Data!F33 | G30: =E30*F30 | H30: =IFERROR(XLOOKUP(Raw_Data!A33,Raw_Data!A:A,Raw_Data!H:H),"N/A") | I30: Clean
A31: =IF(Raw_Data!A34="","Missing",Raw_Data!A34) | B31: =IF(Raw_Data!B34="",DATE(2024,1,1),Raw_Data!B34) | C31: =TRIM(IF(Raw_Data!C34="","Unknown Customer",Raw_Data!C34)) | D31: =IF(Raw_Data!D34="","Unknown Product",Raw_Data!D34) | E31: =ABS(Raw_Data!E34) | F31: =Raw_Data!F34 | G31: =E31*F31 | H31: =IFERROR(XLOOKUP(Raw_Data!A34,Raw_Data!A:A,Raw_Data!H:H),"N/A") | I31: Fixed
A32: =IF(Raw_Data!A35="","Missing",Raw_Data!A35) | B32: =IF(Raw_Data!B35="",DATE(2024,1,1),Raw_Data!B35) | C32: =TRIM(IF(Raw_Data!C35="","Unknown Customer",Raw_Data!C35)) | D32: =IF(Raw_Data!D35="","Unknown Product",Raw_Data!D35) | E32: =ABS(Raw_Data!E35) | F32: =Raw_Data!F35 | G32: =E32*F32 | H32: =IFERROR(XLOOKUP(Raw_Data!A35,Raw_Data!A:A,Raw_Data!H:H),"N/A") | I32: Clean
A33: =IF(Raw_Data!A37="","Missing",Raw_Data!A37) | B33: =IF(Raw_Data!B37="",DATE(2024,1,1),Raw_Data!B37) | C33: =TRIM(IF(Raw_Data!C37="","Unknown Customer",Raw_Data!C37)) | D33: =IF(Raw_Data!D37="","Unknown Product",Raw_Data!D37) | E33: =ABS(Raw_Data!E37) | F33: =Raw_Data!F37 | G33: =E33*F33 | H33: =IFERROR(XLOOKUP(Raw_Data!A37,Raw_Data!A:A,Raw_Data!H:H),"N/A") | I33: Fixed
A34: =IF(Raw_Data!A38="","Missing",Raw_Data!A38) | B34: =IF(Raw_Data!B38="",DATE(2024,1,1),Raw_Data!B38) | C34: =TRIM(IF(Raw_Data!C38="","Unknown Customer",Raw_Data!C38)) | D34: =IF(Raw_Data!D38="","Unknown Product",Raw_Data!D38) | E34: =ABS(Raw_Data!E38) | F34: =Raw_Data!F38 | G34: =E34*F34 | H34: =IFERROR(XLOOKUP(Raw_Data!A38,Raw_Data!A:A,Raw_Data!H:H),"N/A") | I34: Clean
A35: =IF(Raw_Data!A39="","Missing",Raw_Data!A39) | B35: =IF(Raw_Data!B39="",DATE(2024,1,1),Raw_Data!B39) | C35: =TRIM(IF(Raw_Data!C39="","Unknown Customer",Raw_Data!C39)) | D35: =IF(Raw_Data!D39="","Unknown Product",Raw_Data!D39) | E35: =ABS(Raw_Data!E39) | F35: =Raw_Data!F39 | G35: =E35*F35 | H35: =IFERROR(XLOOKUP(Raw_Data!A39,Raw_Data!A:A,Raw_Data!H:H),"N/A") | I35: Fixed
A36: =IF(Raw_Data!A40="","Missing",Raw_Data!A40) | B36: =IF(Raw_Data!B40="",DATE(2024,1,1),Raw_Data!B40) | C36: =TRIM(IF(Raw_Data!C40="","Unknown Customer",Raw_Data!C40)) | D36: =IF(Raw_Data!D40="","Unknown Product",Raw_Data!D40) | E36: =ABS(Raw_Data!E40) | F36: =Raw_Data!F40 | G36: =E36*F36 | H36: =IFERROR(XLOOKUP(Raw_Data!A40,Raw_Data!A:A,Raw_Data!H:H),"N/A") | I36: Clean
A37: =IF(Raw_Data!A42="","Missing",Raw_Data!A42) | B37: =IF(Raw_Data!B42="",DATE(2024,1,1),Raw_Data!B42) | C37: =TRIM(IF(Raw_Data!C42="","Unknown Customer",Raw_Data!C42)) | D37: =IF(Raw_Data!D42="","Unknown Product",Raw_Data!D42) | E37: =ABS(Raw_Data!E42) | F37: =Raw_Data!F42 | G37: =E37*F37 | H37: =IFERROR(XLOOKUP(Raw_Data!A42,Raw_Data!A:A,Raw_Data!H:H),"N/A") | I37: Clean
A38: =IF(Raw_Data!A43="","Missing",Raw_Data!A43) | B38: =IF(Raw_Data!B43="",DATE(2024,1,1),Raw_Data!B43) | C38: =TRIM(IF(Raw_Data!C43="","Unknown Customer",Raw_Data!C43)) | D38: =IF(Raw_Data!D43="","Unknown Product",Raw_Data!D43) | E38: =ABS(Raw_Data!E43) | F38: =Raw_Data!F43 | G38: =E38*F38 | H38: =IFERROR(XLOOKUP(Raw_Data!A43,Raw_Data!A:A,Raw_Data!H:H),"N/A") | I38: Clean
A39: =IF(Raw_Data!A44="","Missing",Raw_Data!A44) | B39: =IF(Raw_Data!B44="",DATE(2024,1,1),Raw_Data!B44) | C39: =TRIM(IF(Raw_Data!C44="","Unknown Customer",Raw_Data!C44)) | D39: =IF(Raw_Data!D44="","Unknown Product",Raw_Data!D44) | E39: =ABS(Raw_Data!E44) | F39: =Raw_Data!F44 | G39: =E39*F39 | H39: =IFERROR(XLOOKUP(Raw_Data!A44,Raw_Data!A:A,Raw_Data!H:H),"N/A") | I39: Fixed
A40: =IF(Raw_Data!A45="","Missing",Raw_Data!A45) | B40: =IF(Raw_Data!B45="",DATE(2024,1,1),Raw_Data!B45) | C40: =TRIM(IF(Raw_Data!C45="","Unknown Customer",Raw_Data!C45)) | D40: =IF(Raw_Data!D45="","Unknown Product",Raw_Data!D45) | E40: =ABS(Raw_Data!E45) | F40: =Raw_Data!F45 | G40: =E40*F40 | H40: =IFERROR(XLOOKUP(Raw_Data!A45,Raw_Data!A:A,Raw_Data!H:H),"N/A") | I40: Fixed
A41: =IF(Raw_Data!A46="","Missing",Raw_Data!A46) | B41: =IF(Raw_Data!B46="",DATE(2024,1,1),Raw_Data!B46) | C41: =TRIM(IF(Raw_Data!C46="","Unknown Customer",Raw_Data!C46)) | D41: =IF(Raw_Data!D46="","Unknown Product",Raw_Data!D46) | E41: =ABS(Raw_Data!E46) | F41: =Raw_Data!F46 | G41: =E41*F41 | H41: =IFERROR(XLOOKUP(Raw_Data!A46,Raw_Data!A:A,Raw_Data!H:H),"N/A") | I41: Fixed
...

Sheet Validation_Checks
A1: VALIDATION CHECKS — Duplicate | Missing Value | Amount Mismatch | Additional Flags
A2: Transaction ID | B2: Date | C2: Customer Name | D2: Product | E2: Quantity | F2: Unit Price ($) | G2: Total Amount ($) | H2: Payment Status | I2: Duplicate Check | J2: Missing Value Check | K2: Amount Mismatch | L2: Additional Flag
A3: TXN1081 | B3: 45376 | C3: Eta Partners | D3: Tablet | E3: 10 | F3: 32000 | G3: 320000 | H3: Refunded | I3: =IF(COUNTIF($A$3:$A$122,A3)>1,"Duplicate","OK") | J3: =IF(OR(A3="",B3="",C3="",D3=""),"Missing","OK") | K3: =IF(ABS(G3-(E3*F3))>0.01,"Mismatch","OK") | L3: OK
A4: TXN1082 | B4: 45402 | C4: Nu Ventures | D4: Printer | E4: 17 | F4: 18000 | G4: 306000 | H4: Paid | I4: =IF(COUNTIF($A$3:$A$122,A4)>1,"Duplicate","OK") | J4: =IF(OR(A4="",B4="",C4="",D4=""),"Missing","OK") | K4: =IF(ABS(G4-(E4*F4))>0.01,"Mismatch","OK") | L4: OK
A5: TXN1083 | B5: 45550 | C5: Iota Ltd | D5: Mouse | E5: 1 | F5: 1200 | G5: 1320 | H5: Pending | I5: =IF(COUNTIF($A$3:$A$122,A5)>1,"Duplicate","OK") | J5: =IF(OR(A5="",B5="",C5="",D5=""),"Missing","OK") | K5: =IF(ABS(G5-(E5*F5))>0.01,"Mismatch","OK") | L5: OK
A6: TXN1020 | B6: 45511 | C6: Beta Ltd | D6: Keyboard | E6: 8 | F6: 3500 | G6: 28000 | H6: Paid | I6: =IF(COUNTIF($A$3:$A$122,A6)>1,"Duplicate","OK") | J6: =IF(OR(A6="",B6="",C6="",D6=""),"Missing","OK") | K6: =IF(ABS(G6-(E6*F6))>0.01,"Mismatch","OK") | L6: OK
A7: TXN1085 | B7: 45647 | C7: Acme Corp | D7: Tablet | E7: 14 | F7: 32000 | G7: 448000 | H7: Refunded | I7: =IF(COUNTIF($A$3:$A$122,A7)>1,"Duplicate","OK") | J7: =IF(OR(A7="",B7="",C7="",D7=""),"Missing","OK") | K7: =IF(ABS(G7-(E7*F7))>0.01,"Mismatch","OK") | L7: OK
A8: TXN1086 | B8: 45309 | C8: Zeta Group | D8: Scanner | E8: 16 | F8: 12000 | G8: 192000 | H8: Paid | I8: =IF(COUNTIF($A$3:$A$122,A8)>1,"Duplicate","OK") | J8: =IF(OR(A8="",B8="",C8="",D8=""),"Missing","OK") | K8: =IF(ABS(G8-(E8*F8))>0.01,"Mismatch","OK") | L8: OK
A9: TXN1087 | B9: 45624 | C9: [BLANK] | D9: Webcam | E9: 1 | F9: 4500 | G9: 4500 | H9: Paid | I9: =IF(COUNTIF($A$3:$A$122,A9)>1,"Duplicate","OK") | J9: =IF(OR(A9="",B9="",C9="",D9=""),"Missing","OK") | K9: =IF(ABS(G9-(E9*F9))>0.01,"Mismatch","OK") | L9: OK
A10: TXN1088 | B10: 45337 | C10: Beta Ltd | D10: Laptop | E10: 15 | F10: 85000 | G10: 1275000 | H10: Paid | I10: =IF(COUNTIF($A$3:$A$122,A10)>1,"Duplicate","OK") | J10: =IF(OR(A10="",B10="",C10="",D10=""),"Missing","OK") | K10: =IF(ABS(G10-(E10*F10))>0.01,"Mismatch","OK") | L10: OK
A11: TXN1020 | B11: 45467 | C11: Eta Partners | D11: Printer | E11: 5 | F11: 18000 | G11: 90000 | H11: Paid | I11: =IF(COUNTIF($A$3:$A$122,A11)>1,"Duplicate","OK") | J11: =IF(OR(A11="",B11="",C11="",D11=""),"Missing","OK") | K11: =IF(ABS(G11-(E11*F11))>0.01,"Mismatch","OK") | L11: OK
A12: TXN1090 | B12: 45632 | C12: Acme Corp | D12: Printer | E12: 8 | F12: 18000 | G12: 144000 | H12: Paid | I12: =IF(COUNTIF($A$3:$A$122,A12)>1,"Duplicate","OK") | J12: =IF(OR(A12="",B12="",C12="",D12=""),"Missing","OK") | K12: =IF(ABS(G12-(E12*F12))>0.01,"Mismatch","OK") | L12: OK
A13: TXN1091 | B13: 45393 | C13: Delta Co | D13: USB Hub | E13: 3 | F13: 2200 | G13: 7260 | H13: Refunded | I13: =IF(COUNTIF($A$3:$A$122,A13)>1,"Duplicate","OK") | J13: =IF(OR(A13="",B13="",C13="",D13=""),"Missing","OK") | K13: =IF(ABS(G13-(E13*F13))>0.01,"Mismatch","OK") | L13: OK
A14: TXN1092 | B14: 45578 | C14: Xi Corp | D14: [BLANK] | E14: 13 | F14: 5000 | G14: 65000 | H14: Paid | I14: =IF(COUNTIF($A$3:$A$122,A14)>1,"Duplicate","OK") | J14: =IF(OR(A14="",B14="",C14="",D14=""),"Missing","OK") | K14: =IF(ABS(G14-(E14*F14))>0.01,"Mismatch","OK") | L14: OK
... A23: TXN1101 | B23: 45511 | C23: Zeta Group | D23: Keyboard | E23: 2 | F23: 3500 | G23: 7000 | H23: Paid | I23: =IF(COUNTIF($A$3:$A$122,A23)>1,"Duplicate","OK") | J23: =IF(OR(A23="",B23="",C23="",D23=""),"Missing","OK") | K23: =IF(ABS(G23-(E23*F23))>0.01,"Mismatch","OK") | L23: OK
A24: TXN1102 | C24: Eta Partners | D24: Keyboard | E24: 19 | F24: 3500 | G24: 66500 | H24: Paid | I24: =IF(COUNTIF($A$3:$A$122,A24)>1,"Duplicate","OK") | J24: =IF(OR(A24="",B24="",C24="",D24=""),"Missing","OK") | K24: =IF(ABS(G24-(E24*F24))>0.01,"Mismatch","OK") | L24: OK
A25: TXN1103 | B25: 45469 | C25: Theta Corp | D25: Scanner | E25: 13 | F25: 12000 | G25: 156000 | H25: Paid | I25: =IF(COUNTIF($A$3:$A$122,A25)>1,"Duplicate","OK") | J25: =IF(OR(A25="",B25="",C25="",D25=""),"Missing","OK") | K25: =IF(ABS(G25-(E25*F25))>0.01,"Mismatch","OK") | L25: OK
A26: TXN1005 | B26: 45375 | C26: Iota Ltd | D26: Monitor | E26: 15 | F26: 22000 | G26: 330000 | H26: Failed | I26: =IF(COUNTIF($A$3:$A$122,A26)>1,"Duplicate","OK") | J26: =IF(OR(A26="",B26="",C26="",D26=""),"Missing","OK") | K26: =IF(ABS(G26-(E26*F26))>0.01,"Mismatch","OK") | L26: OK
A27: TXN1105 | B27: 45539 | C27: Acme Corp | D27: Headphones | E27: 2 | F27: 8500 | G27: 17000 | H27: Pending | I27: =IF(COUNTIF($A$3:$A$122,A27)>1,"Duplicate","OK") | J27: =IF(OR(A27="",B27="",C27="",D27=""),"Missing","OK") | K27: =IF(ABS(G27-(E27*F27))>0.01,"Mismatch","OK") | L27: OK
A28: TXN1106 | B28: 45629 | C28: Epsilon LLC | D28: Laptop | E28: 14 | F28: 85000 | G28: 1190000 | H28: Paid | I28: =IF(COUNTIF($A$3:$A$122,A28)>1,"Duplicate","OK") | J28: =IF(OR(A28="",B28="",C28="",D28=""),"Missing","OK") | K28: =IF(ABS(G28-(E28*F28))>0.01,"Mismatch","OK") | L28: OK
A29: TXN1107 | B29: 45379 | C29: [BLANK] | D29: Tablet | E29: 3 | F29: 32000 | G29: 144000 | H29: Paid | I29: =IF(COUNTIF($A$3:$A$122,A29)>1,"Duplicate","OK") | J29: =IF(OR(A29="",B29="",C29="",D29=""),"Missing","OK") | K29: =IF(ABS(G29-(E29*F29))>0.01,"Mismatch","OK") | L29: OK
A30: TXN1108 | B30: 45369 | C30: Mu Holdings | D30: Printer | E30: 2 | F30: 18000 | G30: 36000 | H30: Pending | I30: =IF(COUNTIF($A$3:$A$122,A30)>1,"Duplicate","OK") | J30: =IF(OR(A30="",B30="",C30="",D30=""),"Missing","OK") | K30: =IF(ABS(G30-(E30*F30))>0.01,"Mismatch","OK") | L30: OK
A31: TXN1005 | B31: 45624 | C31: Iota Ltd | D31: Printer | E31: 1 | F31: 18000 | G31: 18000 | H31: Paid | I31: =IF(COUNTIF($A$3:$A$122,A31)>1,"Duplicate","OK") | J31: =IF(OR(A31="",B31="",C31="",D31=""),"Missing","OK") | K31: =IF(ABS(G31-(E31*F31))>0.01,"Mismatch","OK") | L31: OK
A32: TXN1110 | B32: 45479 | C32: Nu Ventures | D32: Keyboard | E32: 12 | F32: 3500 | G32: 42000 | H32: Failed | I32: =IF(COUNTIF($A$3:$A$122,A32)>1,"Duplicate","OK") | J32: =IF(OR(A32="",B32="",C32="",D32=""),"Missing","OK") | K32: =IF(ABS(G32-(E32*F32))>0.01,"Mismatch","OK") | L32: OK
A33: TXN1111 | B33: 45540 | C33: Kappa Inc | D33: Printer | E33: 10 | F33: 18000 | G33: 180000 | H33: Paid | I33: =IF(COUNTIF($A$3:$A$122,A33)>1,"Duplicate","OK") | J33: =IF(OR(A33="",B33="",C33="",D33=""),"Missing","OK") | K33: =IF(ABS(G33-(E33*F33))>0.01,"Mismatch","OK") | L33: OK
A34: TXN1112 | B34: 45565 | C34: Kappa Inc | D34: [BLANK] | E34: 9 | F34: 5000 | G34: 45000 | H34: Paid | I34: =IF(COUNTIF($A$3:$A$122,A34)>1,"Duplicate","OK") | J34: =IF(OR(A34="",B34="",C34="",D34=""),"Missing","OK") | K34: =IF(ABS(G34-(E34*F34))>0.01,"Mismatch","OK") | L34: OK
A35: TXN1113 | B35: 45297 | C35: Eta Partners | D35: Keyboard | E35: 1 | F35: 3500 | G35: 3500 | H35: Pending | I35: =IF(COUNTIF($A$3:$A$122,A35)>1,"Duplicate","OK") | J35: =IF(OR(A35="",B35="",C35="",D35=""),"Missing","OK") | K35: =IF(ABS(G35-(E35*F35))>0.01,"Mismatch","OK") | L35: OK
A36: TXN1020 | B36: 45458 | C36: Lambda Co | D36: Mouse | E36: 19 | F36: 1200 | G36: 22800 | H36: Failed | I36: =IF(COUNTIF($A$3:$A$122,A36)>1,"Duplicate","OK") | J36: =IF(OR(A36="",B36="",C36="",D36=""),"Missing","OK") | K36: =IF(ABS(G36-(E36*F36))>0.01,"Mismatch","OK") | L36: OK
... A43: TXN1121 | B43: 45601 | C43: Mu Holdings | D43: Scanner | E43: 2 | F43: 12000 | G43: 24000 | H43: Paid | I43: =IF(COUNTIF($A$3:$A$122,A43)>1,"Duplicate","OK") | J43: =IF(OR(A43="",B43="",C43="",D43=""),"Missing","OK") | K43: =IF(ABS(G43-(E43*F43))>0.01,"Mismatch","OK") | L43: OK
A44: TXN1122 | C44: Eta Partners | D44: Printer | E44: 3 | F44: 18000 | G44: 54000 | H44: Failed | I44: =IF(COUNTIF($A$3:$A$122,A44)>1,"Duplicate","OK") | J44: =IF(OR(A44="",B44="",C44="",D44=""),"Missing","OK") | K44: =IF(ABS(G44-(E44*F44))>0.01,"Mismatch","OK") | L44: OK
A45: TXN1123 | B45: 45582 | C45: Gamma Inc | D45: Mouse | E45: 9 | F45: 1200 | G45: 13500 | H45: Pending | I45: =IF(COUNTIF($A$3:$A$122,A45)>1,"Duplicate","OK") | J45: =IF(OR(A45="",B45="",C45="",D45=""),"Missing","OK") | K45: =IF(ABS(G45-(E45*F45))>0.01,"Mismatch","OK") | L45: OK
A46: TXN1001 | B46: 45417 | C46: Eta Partners | D46: Keyboard | E46: 10 | F46: 3500 | G46: 35000 | H46: Pending | I46: =IF(COUNTIF($A$3:$A$122,A46)>1,"Duplicate","OK") | J46: =IF(OR(A46="",B46="",C46="",D46=""),"Missing","OK") | K46: =IF(ABS(G46-(E46*F46))>0.01,"Mismatch","OK") | L46: OK
A47: TXN1125 | B47: 45549 | C47: Nu Ventures | D47: Scanner | E47: -16 | F47: 12000 | G47: -192000 | H47: Paid | I47: =IF(COUNTIF($A$3:$A$122,A47)>1,"Duplicate","OK") | J47: =IF(OR(A47="",B47="",C47="",D47=""),"Missing","OK") | K47: =IF(ABS(G47-(E47*F47))>0.01,"Mismatch","OK") | L47: Negative Qty
A48: TXN1126 | B48: 45571 | C48: Kappa Inc | D48: Laptop | E48: 17 | F48: 85000 | G48: 1445000 | H48: Pending | I48: =IF(COUNTIF($A$3:$A$122,A48)>1,"Duplicate","OK") | J48: =IF(OR(A48="",B48="",C48="",D48=""),"Missing","OK") | K48: =IF(ABS(G48-(E48*F48))>0.01,"Mismatch","OK") | L48: OK
A49: TXN1127 | B49: 45556 | C49: [BLANK] | D49: Headphones | E49: 10 | F49: 8500 | G49: 85000 | H49: Paid | I49: =IF(COUNTIF($A$3:$A$122,A49)>1,"Duplicate","OK") | J49: =IF(OR(A49="",B49="",C49="",D49=""),"Missing","OK") | K49: =IF(ABS(G49-(E49*F49))>0.01,"Mismatch","OK") | L49: OK
A50: TXN1128 | B50: 45324 | C50: Kappa Inc | D50: Webcam | E50: 7 | F50: 4500 | G50: 31500 | H50: Pending | I50: =IF(COUNTIF($A$3:$A$122,A50)>1,"Duplicate","OK") | J50: =IF(OR(A50="",B50="",C50="",D50=""),"Missing","OK") | K50: =IF(ABS(G50-(E50*F50))>0.01,"Mismatch","OK") | L50: OK
A51: TXN1001 | B51: 45454 | C51: Lambda Co | D51: Tablet | E51: 4 | F51: 32000 | G51: 128000 | H51: Paid | I51: =IF(COUNTIF($A$3:$A$122,A51)>1,"Duplicate","OK") | J51: =IF(OR(A51="",B51="",C51="",D51=""),"Missing","OK") | K51: =IF(ABS(G51-(E51*F51))>0.01,"Mismatch","OK") | L51: OK
A52: TXN1130 | B52: 45625 | C52: Beta Ltd | D52: Printer | E52: 17 | F52: 18000 | G52: 306000 | H52: Paid | I52: =IF(COUNTIF($A$3:$A$122,A52)>1,"Duplicate","OK") | J52: =IF(OR(A52="",B52="",C52="",D52=""),"Missing","OK") | K52: =IF(ABS(G52-(E52*F52))>0.01,"Mismatch","OK") | L52: OK
A53: TXN1131 | B53: 45640 | C53: Lambda Co | D53: Printer | E53: 16 | F53: 18000 | G53: 172800 | H53: Failed | I53: =IF(COUNTIF($A$3:$A$122,A53)>1,"Duplicate","OK") | J53: =IF(OR(A53="",B53="",C53="",D53=""),"Missing","OK") | K53: =IF(ABS(G53-(E53*F53))>0.01,"Mismatch","OK") | L53: OK
A54: TXN1132 | B54: 45497 | C54: Beta Ltd | D54: [BLANK] | E54: 8 | F54: 5000 | G54: 40000 | H54: Paid | I54: =IF(COUNTIF($A$3:$A$122,A54)>1,"Duplicate","OK") | J54: =IF(OR(A54="",B54="",C54="",D54=""),"Missing","OK") | K54: =IF(ABS(G54-(E54*F54))>0.01,"Mismatch","OK") | L54: OK
...

Sheet Reconciliation_Summary
B2: RECONCILIATION SUMMARY — Data Quality KPI Report
B4: DATA QUALITY KPIs
B5: KPI Metric | C5: Formula Used | D5: Result
B6: Total Raw Records | C6: =COUNTA(Raw_Data!A:A)-1 | D6: =COUNTA(Raw_Data!A:A)-1
B7: Duplicate Records | C7: =COUNTIF(Validation_Checks!I:I,"Duplicate") | D7: =COUNTIF(Validation_Checks!I3:I122,"Duplicate")
B8: Missing Value Records | C8: =COUNTIF(Validation_Checks!J:J,"Missing") | D8: =COUNTIF(Validation_Checks!J3:J122,"Missing")
B9: Amount Mismatch Records | C9: =COUNTIF(Validation_Checks!K:K,"Mismatch") | D9: =COUNTIF(Validation_Checks!K3:K122,"Mismatch")
B10: Additional Flags (Neg Qty/Zero Prc) | C10: =COUNTIF(Validation_Checks!L:L,"<>OK") | D10: =COUNTIF(Validation_Checks!L3:L122,"<>OK")
B11: Total Error Records | C11: =C7+C8+C9+C10 | D11: =C7+C8+C9+C10
B12: Clean Records (Estimated) | C12: =C6-C11 | D12: =C6-C11
B13: Data Quality Score (%) | C13: =IFERROR(C12/C6,0) | D13: =IFERROR(C12/C6,0)
B14: Error Rate (%) | C14: =IFERROR(C11/C6,0) | D14: =IFERROR(C11/C6,0)
B17: PAYMENT STATUS BREAKDOWN
B18: Status | C18: Count Formula | D18: Count
B19: Paid | C19: =COUNTIF(Raw_Data!H:H,"Paid") | D19: 63
B20: Pending | C20: =COUNTIF(Raw_Data!H:H,"Pending") | D20: 30
B21: Failed | C21: =COUNTIF(Raw_Data!H:H,"Failed") | D21: 9
B22: Refunded | C22: =COUNTIF(Raw_Data!H:H,"Refunded") | D22: 18
B25: FINANCIAL RECONCILIATION
B26: Metric | C26: Formula | D26: Amount ($)
B27: Raw Total (as recorded) | C27: =SUM(Raw_Data!G:G) | D27: 23649385
B28: Corrected Total (Qty×Price) | C28: =SUMPRODUCT(Raw_Data!E3:E122,Raw_Data!F3:F122) | D28: 22984600
B29: Variance ($) | C29: =D27-D28 | D29: 664785
B30: Variance (%) | C30: =IFERROR(D29/D28,0) | D30: 0.028923062
B33: ERRORS BY PRODUCT
B34: Product | C34: Total Records | D34: Error Records
B35: Headphones | C35: 8 | D35: 3
B36: Keyboard | C36: 10 | D36: 4
B37: Laptop | C37: 11 | D37: 2
B38: Monitor | C38: 9 | D38: 7
B39: Mouse | C39: 9 | D39: 5
B40: Printer | C40: 17 | D40: 8
B41: Scanner | C41: 13 | D41: 5
B42: Tablet | C42: 17 | D42: 5
B43: USB Hub | C43: 7 | D43: 5
B44: Unknown | C44: 6 | D44: 6
B45: Webcam | C45: 13 | D45: 5

Sheet Dashboard
B2: 📊 DATA VALIDATION & RECONCILIATION DASHBOARD
B4: Total Records | C4: Total Errors | D4: Clean Records | E4: Data Quality Score
B5: 120 | C5: 55 | D5: 65 | E5: 0.54166667
B7: All raw transactions | C7: Across all error types | D7: Error-free records | E7: % of records clean
B8: Duplicates | C8: Missing Values | D8: Mismatches | E8: Other Flags
B9: 14 | C9: 23 | D9: 18 | E9: 5
B11: Duplicate TXN IDs | C11: Blank fields | D11: Amt ≠ Qty×Price | E11: Neg Qty / Zero Price
B13: CHART DATA TABLES
B14: Error Type | C14: Count | E14: Payment Status | F14: Count | H14: Product | I14: Total Sales ($)
B15: Duplicates | C15: 14 | E15: Paid | F15: 63 | H15: Laptop | I15: 10710000
B16: Missing Values | C16: 23 | E16: Pending | F16: 30 | H16: Tablet | I16: 4640000
B17: Mismatches | C17: 18 | E17: Failed | F17: 9 | H17: Printer | I17: 2772000
B18: Other Flags | C18: 5 | E18: Refunded | F18: 18 | H18: Scanner | I18: 1560000
H19: Monitor | I19: 1386000
H20: Webcam | I20: 639000
H21: Headphones | I21: 476000
H22: Keyboard | I22: 294000
H23: Unknown | I23: 270000
H24: USB Hub | I24: 158400
H25: Mouse | I25: 79200
B60: 📌 KEY INSIGHTS — Data Validation & Reconciliation Analysis
B61: 📊 45.8% of records (55 out of 120) contain at least one data quality issue requiring corrective action.
B62: 🔁 Most common error is 'Missing Values' — systematic data entry or integration issue; source system controls recommended.
B63: 💰 Financial variance of $664,785 found between raw totals and corrected (Qty×Price) values — critical for P&L accuracy.
B64: ⏳ 30 transactions (25.0%) remain PENDING — follow-up required to improve cash collection velocity.
B65: ✅ After cleaning, 65 records (54.2%) are validated and ready for downstream reporting.
B66: 📈 Applying TRIM, IF, and ABS formulas removed whitespace, filled blanks, and fixed sign errors — improving model reliability.
B67: 🏷️ Laptop and Tablet generate highest sales but appear in multiple mismatch rows — source system pricing review recommended.
